<?xml version="1.0" ?>
<robot name="three_link_arm">


  <link name="world"/>


  <joint name="world_to_base" type="fixed">
    <parent link="world"/>
    <child link="base_fixed"/>
    <origin xyz="0 0 0" rpy="0 0 0"/>
  </joint>


  <link name="base_fixed">
    <visual>
      <geometry>
        <box size="0.01 0.01 0.01"/>
      </geometry>
    </visual>
    <collision>
      <geometry>
        <box size="0.01 0.01 0.01"/>
      </geometry>
    </collision>
    <inertial>
      <origin xyz="0 0 0"/>
      <mass value="0.01"/>
      <inertia ixx="1e-6" iyy="1e-6" izz="1e-6"/>
    </inertial>
  </link>


  <link name="base_link">
    <visual>
      <geometry>
        <box size="0.1 0.1 0.1"/>
      </geometry>
      <material name="gray">
        <color rgba="0.5 0.5 0.5 1"/>
      </material>
    </visual>
    <collision>
      <geometry>
        <box size="0.1 0.1 0.1"/>
      </geometry>
    </collision>
    <inertial>
      <origin xyz="0 0 0"/>
      <mass value="0.2"/>
      <inertia ixx="0.0001" iyy="0.0001" izz="0.0001"/>
    </inertial>
  </link>


  <joint name="base_yaw" type="revolute">
    <parent link="base_fixed"/>
    <child link="base_link"/>
    <origin xyz="0 0 0" rpy="0 0 0"/>
    <axis xyz="0 0 1"/>
    <limit lower="-3.14" upper="3.14" effort="100" velocity="2"/>
  </joint>


  <link name="link1">
    <visual>
      <origin xyz="0 0 0.5" rpy="0 0 0"/>
      <geometry>
        <cylinder radius="0.03" length="1.0"/>
      </geometry>
      <material name="red">
        <color rgba="1 0 0 1"/>
      </material>
    </visual>
    <collision>
      <origin xyz="0 0 0.5" rpy="0 0 0"/>
      <geometry>
        <cylinder radius="0.03" length="1.0"/>
      </geometry>
    </collision>
    <inertial>
      <origin xyz="0 0 0.5"/>
      <mass value="1.0"/>
      <inertia ixx="0.0834" iyy="0.0834" izz="0.00045"/>
    </inertial>
  </link>


  <joint name="joint1" type="revolute">
    <parent link="base_link"/>
    <child link="link1"/>
    <origin xyz="0 0 0" rpy="0 0 0"/>
    <axis xyz="0 1 0"/>
    <limit lower="-3.14" upper="3.14" effort="100" velocity="2"/>
  </joint>


  <link name="link2">
    <visual>
      <origin xyz="0 0 0.5" rpy="0 0 0"/>
      <geometry>
        <cylinder radius="0.03" length="1.0"/>
      </geometry>
      <material name="green">
        <color rgba="0 1 0 1"/>
      </material>
    </visual>
    <collision>
      <origin xyz="0 0 0.5" rpy="0 0 0"/>
      <geometry>
        <cylinder radius="0.03" length="1.0"/>
      </geometry>
    </collision>
    <inertial>
      <origin xyz="0 0 0.5"/>
      <mass value="1.0"/>
      <inertia ixx="0.0834" iyy="0.0834" izz="0.00045"/>
    </inertial>
  </link>


  <joint name="joint2" type="revolute">
    <parent link="link1"/>
    <child link="link2"/>
    <origin xyz="0 0 1.0" rpy="0 0 0"/>
    <axis xyz="0 1 0"/>
    <limit lower="-3.14" upper="3.14" effort="100" velocity="2"/>
  </joint>


  <link name="end_effector"/>
  <joint name="ee_fixed" type="fixed">
    <parent link="link2"/>
    <child link="end_effector"/>
    <origin xyz="0 0 1.0" rpy="0 0 0"/>
  </joint>

  <!-- ========== GRIPPER START ========== -->

  <link name="left_finger">
    <visual>
      <origin xyz="0.02 0 0.05" rpy="0 0 0"/>
      <geometry><box size="0.02 0.01 0.1"/></geometry>
      <material name="blue"><color rgba="0 0 1 1"/></material>
    </visual>
    <collision>
      <origin xyz="0.02 0 0.05" rpy="0 0 0"/>
      <geometry><box size="0.02 0.01 0.1"/></geometry>
    </collision>
    <inertial>
      <mass value="0.01"/>
      <inertia ixx="1e-5" iyy="1e-5" izz="1e-5"/>
    </inertial>
  </link>

  <link name="right_finger">
    <visual>
      <origin xyz="-0.02 0 0.05" rpy="0 0 0"/>
      <geometry><box size="0.02 0.01 0.1"/></geometry>
      <material name="blue"><color rgba="0 0 1 1"/></material>
    </visual>
    <collision>
      <origin xyz="-0.02 0 0.05" rpy="0 0 0"/>
      <geometry><box size="0.02 0.01 0.1"/></geometry>
    </collision>
    <inertial>
      <mass value="0.01"/>
      <inertia ixx="1e-5" iyy="1e-5" izz="1e-5"/>
    </inertial>
  </link>

  <joint name="left_finger_joint" type="revolute">
    <parent link="end_effector"/>
    <child link="left_finger"/>
    <origin xyz="0.02 0 0" rpy="0 0 0"/>
    <axis xyz="0 1 0"/>
    <limit lower="-0.6" upper="0.0" effort="50" velocity="1.0"/>
  </joint>

  <joint name="right_finger_joint" type="revolute">
    <parent link="end_effector"/>
    <child link="right_finger"/>
    <origin xyz="-0.02 0 0" rpy="0 0 0"/>
    <axis xyz="0 -1 0"/>
    <limit lower="0.0" upper="0.6" effort="50" velocity="1.0"/>
  </joint>

  <!-- ========== GRIPPER END ========== -->

</robot>
